Workbook

Sheet Partner1992
A1: Reporter Name | B1: Partner Name | C1: Year | D1: Import Partner Share (%) | E1: Trade Flow | F1: No Of exported HS6 digit Products | G1: No Of imported HS6 digit Products | H1: Export Share in Total Products (%) | I1: Import Share in Total Products (%) | J1: Trade Balance (US$ Thousand) | K1: Export (US$ Thousand) | L1: Import (US$ Thousand) | M1: Export Partner Share (%) | N1: AHS Simple Average (%) | O1: AHS Weighted Average (%) | P1: AHS Total Tariff Lines | Q1: AHS Dutiable Tariff Lines Share (%) | R1: AHS Duty Free Tariff Lines Share (%) | S1: AHS Specific Tariff Lines Share (%) | T1: AHS AVE Tariff Lines Share (%) | U1: AHS MaxRate (%) | V1: AHS MinRate (%) | W1: AHS SpecificDuty Imports(US$ Thousand) | X1: AHS Dutiable Imports (US$ Thousand) | Y1: AHS Duty Free Imports (US$ Thousand) | Z1: MFN Simple Average (%) | AA1: MFN Weighted Average (%) | AB1: MFN Total Tariff Lines | AC1: MFN Dutiable Tariff Lines Share (%) | AD1: MFN Duty Free Tariff Lines Share (%) | AE1: MFN Specific Tariff Lines Share (%) | AF1: MFN AVE Tariff Lines Share (%) | AG1: MFN MaxRate (%) | AH1: MFN MinRate (%) | AI1: MFN SpecificDuty Imports (US$ Thousand) | AJ1: MFN Dutiable Imports (US$ Thousand) | AK1: MFN Duty Free Imports (US$ Thousand) | AL1: No Of Tariff Agreement
A2: Hungary | B2: World | C2: 1992 | D2: 100 | E2: Exports & Imports | F2: 2878 | G2: 4186 | H2: 100 | I2: 100 | J2: -818605.06 | K2: 10054975 | L2: 10873581 | M2: 100
A3: Hungary | B3: Europe & Central Asia | C3: 1992 | D3: 82.25 | E3: Exports & Imports | F3: 2855 | G3: 4174 | H3: 99.2 | I3: 99.71 | J3: -472564.1 | K3: 8470842 | L3: 8943406.1 | M3: 84.25
A4: Hungary | B4: Germany | C4: 1992 | D4: 23.84 | E4: Exports & Imports | F4: 2284 | G4: 3861 | H4: 79.36 | I4: 92.24 | J4: 288537.86 | K4: 2880841 | L4: 2592303.1 | M4: 28.65
A5: Hungary | B5: Russian Federation | C5: 1992 | D5: 16.47 | E5: Exports & Imports | F5: 1749 | G5: 1238 | H5: 60.77 | I5: 29.57 | J5: -442352 | K5: 1348554 | L5: 1790906 | M5: 13.41
A6: Hungary | B6: Austria | C6: 1992 | D6: 14.59 | E6: Exports & Imports | F6: 1974 | G6: 3545 | H6: 68.59 | I6: 84.69 | J6: -506808.96 | K6: 1079298.1 | L6: 1586107 | M6: 10.73
A7: Hungary | B7: Italy | C7: 1992 | D7: 6.39 | E7: Exports & Imports | F7: 1220 | G7: 2659 | H7: 42.39 | I7: 63.52 | J7: 203292.03 | K7: 897590.02 | L7: 694297.98 | M7: 8.93
A8: Hungary | B8: Czechoslovakia | C8: 1992 | D8: 4.29 | E8: Exports & Imports | F8: 1555 | G8: 2025 | H8: 54.03 | I8: 48.38 | J8: -218100.99 | K8: 248355.01 | L8: 466456 | M8: 2.47
A9: Hungary | B9: East Asia & Pacific | C9: 1992 | D9: 4.26 | E9: Exports & Imports | F9: 619 | G9: 1764 | H9: 21.51 | I9: 42.14 | J9: -263343.99 | K9: 200210 | L9: 463553.99 | M9: 1.99
A10: Hungary | B10: North America | C10: 1992 | D10: 3.26 | E10: Exports & Imports | F10: 810 | G10: 2034 | H10: 28.14 | I10: 48.59 | J10: 23292.99 | K10: 377760.98 | L10: 354467.99 | M10: 3.76
A11: Hungary | B11: Switzerland | C11: 1992 | D11: 3.18 | E11: Exports & Imports | F11: 945 | G11: 2268 | H11: 32.84 | I11: 54.18 | J11: -151863.01 | K11: 194079.01 | L11: 345942.02 | M11: 1.93
A12: Hungary | B12: France | C12: 1992 | D12: 3.12 | E12: Exports & Imports | F12: 826 | G12: 2250 | H12: 28.7 | I12: 53.75 | J12: -4752 | K12: 334199.01 | L12: 338951.01 | M12: 3.32
A13: Hungary | B13: Netherlands | C13: 1992 | D13: 3.01 | E13: Exports & Imports | F13: 877 | G13: 2237 | H13: 30.47 | I13: 53.44 | J13: -97635.98 | K13: 230182 | L13: 327817.98 | M13: 2.29
... A27: Hungary | B27: Romania | C27: 1992 | D27: 0.57 | E27: Exports & Imports | F27: 1333 | G27: 694 | H27: 46.32 | I27: 16.58 | J27: 117930.99 | K27: 179828.99 | L27: 61898 | M27: 1.79
A28: Hungary | B28: Other Asia, nes | C28: 1992 | D28: 0.54 | E28: Exports & Imports | J28: -24637 | K28: 34524 | L28: 59161 | M28: 0.34
A29: Hungary | B29: Korea, Rep. | C29: 1992 | D29: 0.5 | E29: Exports & Imports | F29: 68 | G29: 363 | H29: 2.36 | I29: 8.67 | J29: -40929 | K29: 13011 | L29: 53940 | M29: 0.13
A30: Hungary | B30: Middle East & North Africa | C30: 1992 | D30: 0.43 | E30: Exports & Imports | F30: 799 | G30: 670 | H30: 27.76 | I30: 16.01 | J30: 299895 | K30: 347170 | L30: 47275 | M30: 3.45
A31: Hungary | B31: China | C31: 1992 | D31: 0.37 | E31: Exports & Imports | F31: 112 | G31: 618 | H31: 3.89 | I31: 14.76 | J31: -24783 | K31: 14963 | L31: 39746 | M31: 0.15
A32: Hungary | B32: Canada | C32: 1992 | D32: 0.35 | E32: Exports & Imports | F32: 264 | G32: 515 | H32: 9.17 | I32: 12.3 | J32: 9095 | K32: 46859 | L32: 37764 | M32: 0.47
A33: Hungary | B33: Sub-Saharan Africa | C33: 1992 | D33: 0.34 | E33: Exports & Imports | F33: 343 | G33: 260 | H33: 11.92 | I33: 6.21 | J33: -13177 | K33: 23975 | L33: 37152 | M33: 0.24
A34: Hungary | B34: South Asia | C34: 1992 | D34: 0.31 | E34: Exports & Imports | F34: 200 | G34: 366 | H34: 6.95 | I34: 8.74 | J34: 20181 | K34: 54154 | L34: 33973 | M34: 0.54
A35: Hungary | B35: Singapore | C35: 1992 | D35: 0.31 | E35: Exports & Imports | F35: 78 | G35: 243 | H35: 2.71 | I35: 5.81 | J35: -26603 | K35: 6930 | L35: 33533 | M35: 0.07
A36: Hungary | B36: Greece | C36: 1992 | D36: 0.29 | E36: Exports & Imports | F36: 444 | G36: 316 | H36: 15.43 | I36: 7.55 | J36: 41710 | K36: 72794 | L36: 31084 | M36: 0.72
A37: Hungary | B37: Israel | C37: 1992 | D37: 0.28 | E37: Exports & Imports | F37: 199 | G37: 415 | H37: 6.91 | I37: 9.91 | J37: 1505 | K37: 31997 | L37: 30492 | M37: 0.32
A38: Hungary | B38: India | C38: 1992 | D38: 0.26 | E38: Exports & Imports | F38: 110 | G38: 305 | H38: 3.82 | I38: 7.29 | J38: -8868 | K38: 19114 | L38: 27982 | M38: 0.19
A39: Hungary | B39: Turkey | C39: 1992 | D39: 0.24 | E39: Exports & Imports | F39: 307 | G39: 427 | H39: 10.67 | I39: 10.2 | J39: 96111 | K39: 121880 | L39: 25769 | M39: 1.21
A40: Hungary | B40: Indonesia | C40: 1992 | D40: 0.18 | E40: Exports & Imports | F40: 55 | G40: 137 | H40: 1.91 | I40: 3.27 | J40: -10942 | K40: 8760 | L40: 19702 | M40: 0.09
... A94: Hungary | B94: Bahamas, The | C94: 1992 | D94: 0 | E94: Exports & Imports | F94: 9 | G94: 13 | H94: 0.31 | I94: 0.31 | J94: 287 | K94: 423 | L94: 136 | M94: 0
A95: Hungary | B95: Belize | C95: 1992 | D95: 0 | E95: Exports & Imports | G95: 1 | I95: 0.02 | L95: 5
A96: Hungary | B96: Bermuda | C96: 1992 | D96: 0 | E96: Exports & Imports | F96: 6 | G96: 1 | H96: 0.21 | I96: 0.02 | J96: 365 | K96: 492 | L96: 127 | M96: 0
A97: Hungary | B97: Bolivia | C97: 1992 | D97: 0 | E97: Exports & Imports | F97: 4 | G97: 2 | H97: 0.14 | I97: 0.05 | J97: 23 | K97: 47 | L97: 24 | M97: 0
A98: Hungary | B98: Barbados | C98: 1992 | D98: 0 | E98: Exports & Imports | F98: 3 | G98: 1 | H98: 0.1 | I98: 0.02 | J98: 119 | K98: 120 | L98: 1 | M98: 0
A99: Hungary | B99: Central African Republic | C99: 1992 | D99: 0 | E99: Exports & Imports | F99: 1 | G99: 3 | H99: 0.03 | I99: 0.07 | J99: -1 | K99: 3 | L99: 4 | M99: 0
A100: Hungary | B100: Cameroon | C100: 1992 | D100: 0 | E100: Exports & Imports | F100: 4 | G100: 5 | H100: 0.14 | I100: 0.12 | J100: 411 | K100: 578 | L100: 167 | M100: 0.01
A101: Hungary | B101: Congo, Rep. | C101: 1992 | D101: 0 | E101: Exports & Imports | F101: 3 | G101: 5 | H101: 0.1 | I101: 0.12 | J101: 2 | K101: 18 | L101: 16 | M101: 0
A102: Hungary | B102: Comoros | C102: 1992 | D102: 0 | E102: Exports & Imports | F102: 1 | G102: 1 | H102: 0.03 | I102: 0.02 | J102: -1 | K102: 4 | L102: 5 | M102: 0
A103: Hungary | B103: Cuba | C103: 1992 | D103: 0 | E103: Exports & Imports | F103: 28 | G103: 8 | H103: 0.97 | I103: 0.19 | J103: 7974 | K103: 8173 | L103: 199 | M103: 0.08
A104: Hungary | B104: Djibouti | C104: 1992 | D104: 0 | E104: Exports & Imports | F104: 1 | G104: 2 | H104: 0.03 | I104: 0.05 | J104: 23 | K104: 29 | L104: 6 | M104: 0
A105: Hungary | B105: Dominican Republic | C105: 1992 | D105: 0 | E105: Exports & Imports | F105: 6 | G105: 3 | H105: 0.21 | I105: 0.07 | J105: 616 | K105: 667 | L105: 51 | M105: 0.01
A106: Hungary | B106: Falkland Island | C106: 1992 | D106: 0 | E106: Exports & Imports | F106: 1 | G106: 2 | H106: 0.03 | I106: 0.05 | J106: 19 | K106: 37 | L106: 18 | M106: 0
...

Sheet Partner2001
A1: Reporter Name | B1: Partner Name | C1: Import Partner Share (%) | D1: Year | E1: Trade Flow | F1: No Of exported HS6 digit Products | G1: No Of imported HS6 digit Products | H1: Export Share in Total Products (%) | I1: Import Share in Total Products (%) | J1: Trade Balance (US$ Thousand) | K1: Export (US$ Thousand) | L1: Import (US$ Thousand) | M1: Import Partner Share (%) | N1: Export Partner Share (%) | O1: AHS Simple Average (%) | P1: AHS Weighted Average (%) | Q1: AHS Total Tariff Lines | R1: AHS Dutiable Tariff Lines Share (%) | S1: AHS Duty Free Tariff Lines Share (%) | T1: AHS Specific Tariff Lines Share (%) | U1: AHS AVE Tariff Lines Share (%) | V1: AHS MaxRate (%) | W1: AHS MinRate (%) | X1: AHS SpecificDuty Imports(US$ Thousand) | Y1: AHS Dutiable Imports (US$ Thousand) | Z1: AHS Duty Free Imports (US$ Thousand) | AA1: MFN Simple Average (%) | AB1: MFN Weighted Average (%) | AC1: MFN Total Tariff Lines | AD1: MFN Dutiable Tariff Lines Share (%) | AE1: MFN Duty Free Tariff Lines Share (%) | AF1: MFN Specific Tariff Lines Share (%) | AG1: MFN AVE Tariff Lines Share (%) | AH1: MFN MaxRate (%) | AI1: MFN MinRate (%) | AJ1: MFN SpecificDuty Imports (US$ Thousand) | AK1: MFN Dutiable Imports (US$ Thousand) | AL1: MFN Duty Free Imports (US$ Thousand) | AM1: No Of Tariff Agreement
A2: Hungary | B2: World | C2: 100 | D2: 2001 | E2: Exports & Imports | F2: 3353 | G2: 4358 | H2: 100 | I2: 100 | J2: -3184015 | K2: 30497719 | L2: 33681734 | M2: 100 | N2: 100
A3: Hungary | B3: Europe & Central Asia | C3: 76.67 | D3: 2001 | E3: Exports & Imports | F3: 3345 | G3: 4314 | H3: 99.76 | I3: 98.99 | J3: 1760937 | K3: 27586086 | L3: 25825149 | M3: 76.67 | N3: 90.45
A4: Hungary | B4: Germany | C4: 24.92 | D4: 2001 | E4: Exports & Imports | F4: 2582 | G4: 3849 | H4: 77.01 | I4: 88.32 | J4: 2466361 | K4: 10858885 | L4: 8392524 | M4: 24.92 | N4: 35.61
A5: Hungary | B5: East Asia & Pacific | C5: 15.04 | D5: 2001 | E5: Exports & Imports | F5: 1018 | G5: 2831 | H5: 30.36 | I5: 64.96 | J5: -4372212 | K5: 693186 | L5: 5065398 | M5: 15.04 | N5: 2.27
A6: Hungary | B6: Italy | C6: 7.86 | D6: 2001 | E6: Exports & Imports | F6: 1756 | G6: 3351 | H6: 52.37 | I6: 76.89 | J6: -742247 | K6: 1905165 | L6: 2647412 | M6: 7.86 | N6: 6.25
A7: Hungary | B7: Austria | C7: 7.39 | D7: 2001 | E7: Exports & Imports | F7: 2248 | G7: 3077 | H7: 67.04 | I7: 70.61 | J7: -71025 | K7: 2416789 | L7: 2487814 | M7: 7.39 | N7: 7.92
A8: Hungary | B8: Russian Federation | C8: 7.03 | D8: 2001 | E8: Exports & Imports | F8: 1058 | G8: 677 | H8: 31.55 | I8: 15.53 | J8: -1896981 | K8: 472337 | L8: 2369318 | M8: 7.03 | N8: 1.55
A9: Hungary | B9: France | C9: 4.69 | D9: 2001 | E9: Exports & Imports | F9: 1391 | G9: 2961 | H9: 41.49 | I9: 67.94 | J9: 239652 | K9: 1818804 | L9: 1579152 | M9: 4.69 | N9: 5.96
A10: Hungary | B10: Japan | C10: 4.62 | D10: 2001 | E10: Exports & Imports | F10: 452 | G10: 1665 | H10: 13.48 | I10: 38.21 | J10: -1382587 | K10: 172775 | L10: 1555362 | M10: 4.62 | N10: 0.57
A11: Hungary | B11: North America | C11: 4.43 | D11: 2001 | E11: Exports & Imports | F11: 1337 | G11: 2659 | H11: 39.87 | I11: 61.01 | J11: 79175 | K11: 1571342 | L11: 1492167 | M11: 4.43 | N11: 5.15
A12: Hungary | B12: United States | C12: 4.23 | D12: 2001 | E12: Exports & Imports | F12: 1266 | G12: 2588 | H12: 37.76 | I12: 59.38 | J12: 101064 | K12: 1525300 | L12: 1424236 | M12: 4.23 | N12: 5
A13: Hungary | B13: China | C13: 3.96 | D13: 2001 | E13: Exports & Imports | F13: 304 | G13: 1980 | H13: 9.07 | I13: 45.43 | J13: -1220876 | K13: 112698 | L13: 1333574 | M13: 3.96 | N13: 0.37
... A21: Hungary | B21: Singapore | C21: 1.54 | D21: 2001 | E21: Exports & Imports | F21: 201 | G21: 398 | H21: 5.99 | I21: 9.13 | J21: -369837 | K21: 148515 | L21: 518352 | M21: 1.54 | N21: 0.49
A22: Hungary | B22: Other Asia, nes | C22: 1.44 | D22: 2001 | E22: Exports & Imports | J22: -437335 | K22: 47599 | L22: 484934 | M22: 1.44 | N22: 0.16
A23: Hungary | B23: Malaysia | C23: 1.42 | D23: 2001 | E23: Exports & Imports | F23: 136 | G23: 561 | H23: 4.06 | I23: 12.87 | J23: -425456 | K23: 52107 | L23: 477563 | M23: 1.42 | N23: 0.17
A24: Hungary | B24: Switzerland | C24: 1.39 | D24: 2001 | E24: Exports & Imports | F24: 1198 | G24: 1985 | H24: 35.73 | I24: 45.55 | J24: -86067 | K24: 382378 | L24: 468445 | M24: 1.39 | N24: 1.25
A25: Hungary | B25: Korea, Rep. | C25: 1.23 | D25: 2001 | E25: Exports & Imports | F25: 197 | G25: 1065 | H25: 5.88 | I25: 24.44 | J25: -376489 | K25: 36687 | L25: 413176 | M25: 1.23 | N25: 0.12
A26: Hungary | B26: Latin America & Caribbean | C26: 1.21 | D26: 2001 | E26: Exports & Imports | F26: 514 | G26: 912 | H26: 15.33 | I26: 20.93 | J26: -243239 | K26: 165654 | L26: 408893 | M26: 1.21 | N26: 0.54
A27: Hungary | B27: Romania | C27: 1.07 | D27: 2001 | E27: Exports & Imports | F27: 2485 | G27: 1169 | H27: 74.11 | I27: 26.82 | J27: 402187 | K27: 764230 | L27: 362043 | M27: 1.07 | N27: 2.51
A28: Hungary | B28: Finland | C28: 1.05 | D28: 2001 | E28: Exports & Imports | F28: 553 | G28: 1030 | H28: 16.49 | I28: 23.63 | J28: -160024 | K28: 193624 | L28: 353648 | M28: 1.05 | N28: 0.63
A29: Hungary | B29: Sweden | C29: 1.03 | D29: 2001 | E29: Exports & Imports | F29: 788 | G29: 1564 | H29: 23.5 | I29: 35.89 | J29: -47182 | K29: 301182 | L29: 348364 | M29: 1.03 | N29: 0.99
A30: Hungary | B30: Ukraine | C30: 0.88 | D30: 2001 | E30: Exports & Imports | F30: 1359 | G30: 624 | H30: 40.53 | I30: 14.32 | J30: -85943 | K30: 209282 | L30: 295225 | M30: 0.88 | N30: 0.69
A31: Hungary | B31: Thailand | C31: 0.77 | D31: 2001 | E31: Exports & Imports | F31: 127 | G31: 741 | H31: 3.79 | I31: 17 | J31: -243323 | K31: 16365 | L31: 259688 | M31: 0.77 | N31: 0.05
A32: Hungary | B32: Brazil | C32: 0.67 | D32: 2001 | E32: Exports & Imports | F32: 213 | G32: 412 | H32: 6.35 | I32: 9.45 | J32: -169604 | K32: 56094 | L32: 225698 | M32: 0.67 | N32: 0.18
A33: Hungary | B33: Denmark | C33: 0.58 | D33: 2001 | E33: Exports & Imports | F33: 581 | G33: 1363 | H33: 17.33 | I33: 31.28 | J33: -39144 | K33: 156384 | L33: 195528 | M33: 0.58 | N33: 0.51
A34: Hungary | B34: Ireland | C34: 0.56 | D34: 2001 | E34: Exports & Imports | F34: 254 | G34: 566 | H34: 7.58 | I34: 12.99 | J34: 142345 | K34: 329507 | L34: 187162 | M34: 0.56 | N34: 1.08
... A112: Hungary | B112: Congo, Rep. | C112: 0 | D112: 2001 | E112: Exports & Imports | F112: 2 | G112: 1 | H112: 0.06 | I112: 0.02 | J112: -21 | K112: 6 | L112: 27 | M112: 0 | N112: 0
A113: Hungary | B113: Comoros | C113: 0 | D113: 2001 | E113: Exports & Imports | G113: 2 | I113: 0.05 | L113: 16 | M113: 0
A114: Hungary | B114: Cuba | C114: 0 | D114: 2001 | E114: Exports & Imports | F114: 25 | G114: 8 | H114: 0.75 | I114: 0.18 | J114: -139 | K114: 269 | L114: 408 | M114: 0 | N114: 0
A115: Hungary | B115: Cayman Islands | C115: 0 | D115: 2001 | E115: Exports & Imports | F115: 2 | G115: 1 | H115: 0.06 | I115: 0.02 | J115: 214 | K115: 215 | L115: 1 | M115: 0 | N115: 0
A116: Hungary | B116: Dominica | C116: 0 | D116: 2001 | E116: Exports & Imports | F116: 3 | G116: 7 | H116: 0.09 | I116: 0.16 | J116: -92 | K116: 28 | L116: 120 | M116: 0 | N116: 0
A117: Hungary | B117: Dominican Republic | C117: 0 | D117: 2001 | E117: Exports & Imports | F117: 7 | G117: 22 | H117: 0.21 | I117: 0.5 | J117: 380 | K117: 757 | L117: 377 | M117: 0 | N117: 0
A118: Hungary | B118: Algeria | C118: 0 | D118: 2001 | E118: Exports & Imports | F118: 78 | G118: 3 | H118: 2.33 | I118: 0.07 | J118: 10877 | K118: 11016 | L118: 139 | M118: 0 | N118: 0.04
A119: Hungary | B119: Ethiopia(excludes Eritrea) | C119: 0 | D119: 2001 | E119: Exports & Imports | F119: 31 | G119: 6 | H119: 0.92 | I119: 0.14 | J119: 2296 | K119: 2449 | L119: 153 | M119: 0 | N119: 0.01
A120: Hungary | B120: Fiji | C120: 0 | D120: 2001 | E120: Exports & Imports | F120: 5 | G120: 4 | H120: 0.15 | I120: 0.09 | J120: 12 | K120: 19 | L120: 7 | M120: 0 | N120: 0
A121: Hungary | B121: Falkland Island | C121: 0 | D121: 2001 | E121: Exports & Imports | G121: 3 | I121: 0.07 | L121: 3 | M121: 0
A122: Hungary | B122: Micronesia, Fed. Sts. | C122: 0 | D122: 2001 | E122: Exports & Imports | G122: 1 | I122: 0.02 | L122: 10 | M122: 0
A123: Hungary | B123: Gabon | C123: 0 | D123: 2001 | E123: Exports & Imports | F123: 17 | G123: 4 | H123: 0.51 | I123: 0.09 | J123: -19 | K123: 161 | L123: 180 | M123: 0 | N123: 0
A124: Hungary | B124: Georgia | C124: 0 | D124: 2001 | E124: Exports & Imports | F124: 50 | G124: 8 | H124: 1.49 | I124: 0.18 | J124: 5476 | K124: 5495 | L124: 19 | M124: 0 | N124: 0.02
...

Sheet Partner2008
A1: Reporter Name | B1: Partner Name | C1: Import Partner Share (%) | D1: Year | E1: Trade Flow | F1: No Of exported HS6 digit Products | G1: No Of imported HS6 digit Products | H1: Export Share in Total Products (%) | I1: Import Share in Total Products (%) | J1: Trade Balance (US$ Thousand) | K1: Export (US$ Thousand) | L1: Import (US$ Thousand) | M1: Import Partner Share (%) | N1: Export Partner Share (%) | O1: AHS Simple Average (%) | P1: AHS Weighted Average (%) | Q1: AHS Total Tariff Lines | R1: AHS Dutiable Tariff Lines Share (%) | S1: AHS Duty Free Tariff Lines Share (%) | T1: AHS Specific Tariff Lines Share (%) | U1: AHS AVE Tariff Lines Share (%) | V1: AHS MaxRate (%) | W1: AHS MinRate (%) | X1: AHS SpecificDuty Imports(US$ Thousand) | Y1: AHS Dutiable Imports (US$ Thousand) | Z1: AHS Duty Free Imports (US$ Thousand) | AA1: MFN Simple Average (%) | AB1: MFN Weighted Average (%) | AC1: MFN Total Tariff Lines | AD1: MFN Dutiable Tariff Lines Share (%) | AE1: MFN Duty Free Tariff Lines Share (%) | AF1: MFN Specific Tariff Lines Share (%) | AG1: MFN AVE Tariff Lines Share (%) | AH1: MFN MaxRate (%) | AI1: MFN MinRate (%) | AJ1: MFN SpecificDuty Imports (US$ Thousand) | AK1: MFN Dutiable Imports (US$ Thousand) | AL1: MFN Duty Free Imports (US$ Thousand) | AM1: No Of Tariff Agreement
A2: Hungary | B2: World | C2: 100 | D2: 2008 | E2: Exports & Imports | F2: 3057 | G2: 3977 | H2: 100 | I2: 100 | J2: -573558 | K2: 108211166 | L2: 108784724 | M2: 100 | N2: 100 | O2: 2.27 | P2: 1.11 | Q2: 83800 | R2: 37.47 | S2: 58.42 | T2: 0.9 | U2: 3.21 | V2: 174.79 | W2: 0 | X2: 37026 | Y2: 9521416 | Z2: 19567735 | AA2: 5.46 | AB2: 1.74 | AC2: 14237 | AD2: 62.98 | AE2: 26.52 | AF2: 0.19 | AG2: 1.59 | AH2: 457.68 | AI2: 0 | AJ2: 40353 | AK2: 14280897 | AL2: 14808254
A3: Hungary | B3: Europe & Central Asia | C3: 82.04 | D3: 2008 | E3: Exports & Imports | F3: 3048 | G3: 3967 | H3: 99.71 | I3: 99.75 | J3: 9585438 | K3: 98834544 | L3: 89249106 | M3: 82.04 | N3: 91.33 | O3: 1.07 | P3: 0.68 | Q3: 23806 | R3: 15.25 | S3: 80.57 | T3: 0.87 | U3: 3.32 | V3: 174.79 | W3: 0 | X3: 6492 | Y3: 587386 | Z3: 9189477 | AA3: 4.5 | AB3: 1.49 | AC3: 8894 | AD3: 67.01 | AE3: 25.7 | AF3: 0.39 | AG3: 2.33 | AH3: 174.79 | AI3: 0 | AJ3: 9485 | AK3: 2762470 | AL3: 7014393
A4: Hungary | B4: Germany | C4: 25.53 | D4: 2008 | E4: Exports & Imports | F4: 2102 | G4: 3709 | H4: 68.76 | I4: 93.26 | J4: 1132719 | K4: 28909331 | L4: 27776612 | M4: 25.53 | N4: 26.72
A5: Hungary | B5: East Asia & Pacific | C5: 12.96 | D5: 2008 | E5: Exports & Imports | F5: 1219 | G5: 2506 | H5: 39.88 | I5: 63.01 | J5: -11372201 | K5: 2723239 | L5: 14095440 | M5: 12.96 | N5: 2.52 | O5: 2.73 | P5: 1.1 | Q5: 29597 | R5: 49.8 | S5: 47.5 | T5: 0.71 | U5: 1.99 | V5: 174.79 | W5: 0 | X5: 8740 | Y5: 5978915 | Z5: 7980931 | AA5: 4.35 | AB5: 1.75 | AC5: 8543 | AD5: 69.34 | AE5: 26.06 | AF5: 0.23 | AG5: 1.1 | AH5: 174.79 | AI5: 0 | AJ5: 8740 | AK5: 8218106 | AL5: 5741740
A6: Hungary | B6: Russian Federation | C6: 9.34 | D6: 2008 | E6: Exports & Imports | F6: 1096 | G6: 448 | H6: 35.85 | I6: 11.26 | J6: -6285083 | K6: 3872211 | L6: 10157294 | M6: 9.34 | N6: 3.58 | O6: 0.97 | P6: 0.06 | Q6: 2292 | R6: 20.2 | S6: 74.3 | T6: 1 | U6: 4.49 | V6: 50.15 | W6: 0 | X6: 520 | Y6: 112430 | Z6: 5379981 | AA6: 2.97 | AB6: 0.4 | AC6: 2292 | AD6: 59.42 | AE6: 34.9 | AF6: 1 | AG6: 4.67 | AH6: 50.15 | AI6: 0 | AJ6: 520 | AK6: 801032 | AL6: 4691379
A7: Hungary | B7: Austria | C7: 6.17 | D7: 2008 | E7: Exports & Imports | F7: 1796 | G7: 3173 | H7: 58.75 | I7: 79.78 | J7: -1412072 | K7: 5303746 | L7: 6715818 | M7: 6.17 | N7: 4.9
A8: Hungary | B8: China | C8: 5.63 | D8: 2008 | E8: Exports & Imports | F8: 656 | G8: 2161 | H8: 21.46 | I8: 54.34 | J8: -5019133 | K8: 1110516 | L8: 6129649 | M8: 5.63 | N8: 1.03 | O8: 2.06 | P8: 0.31 | Q8: 7330 | R8: 31.79 | S8: 65.58 | T8: 0.76 | U8: 1.87 | V8: 174.79 | W8: 0 | X8: 2132 | Y8: 1556512 | Z8: 4553777 | AA8: 4.28 | AB8: 1.56 | AC8: 7330 | AD8: 70.53 | AE8: 26.62 | AF8: 0.76 | AG8: 2.09 | AH8: 174.79 | AI8: 0 | AJ8: 2132 | AK8: 3422054 | AL8: 2688235
A9: Hungary | B9: Netherlands | C9: 4.52 | D9: 2008 | E9: Exports & Imports | F9: 1005 | G9: 2577 | H9: 32.88 | I9: 64.8 | J9: -1832993 | K9: 3087636 | L9: 4920629 | M9: 4.52 | N9: 2.85
A10: Hungary | B10: France | C10: 4.35 | D10: 2008 | E10: Exports & Imports | F10: 1168 | G10: 2583 | H10: 38.21 | I10: 64.95 | J10: 343386 | K10: 5072915 | L10: 4729529 | M10: 4.35 | N10: 4.69
A11: Hungary | B11: Italy | C11: 4.24 | D11: 2008 | E11: Exports & Imports | F11: 1404 | G11: 2951 | H11: 45.93 | I11: 74.2 | J11: 1146600 | K11: 5759189 | L11: 4612589 | M11: 4.24 | N11: 5.32
A12: Hungary | B12: Poland | C12: 3.96 | D12: 2008 | E12: Exports & Imports | F12: 1456 | G12: 2250 | H12: 47.63 | I12: 56.58 | J12: -4203 | K12: 4302175 | L12: 4306378 | M12: 3.96 | N12: 3.98
A13: Hungary | B13: Czech Republic | C13: 3.79 | D13: 2008 | E13: Exports & Imports | F13: 1706 | G13: 2338 | H13: 55.81 | I13: 58.79 | J13: 183914 | K13: 4306426 | L13: 4122512 | M13: 3.79 | N13: 3.98
A14: Hungary | B14: Slovak Republic | C14: 3.53 | D14: 2008 | E14: Exports & Imports | F14: 2147 | G14: 2218 | H14: 70.23 | I14: 55.77 | J14: 1266404 | K14: 5104987 | L14: 3838583 | M14: 3.53 | N14: 4.72
A15: Hungary | B15: Japan | C15: 2.58 | D15: 2008 | E15: Exports & Imports | F15: 592 | G15: 1106 | H15: 19.37 | I15: 27.81 | J15: -2316248 | K15: 492511 | L15: 2808759 | M15: 2.58 | N15: 0.46 | O15: 3.22 | P15: 2.17 | Q15: 4164 | R15: 70.53 | S15: 28.7 | T15: 0.34 | U15: 0.43 | V15: 40.6 | W15: 0 | X15: 50 | Y15: 1854157 | Z15: 850141 | AA15: 3.22 | AB15: 2.17 | AC15: 4164 | AD15: 70.53 | AE15: 28.7 | AF15: 0.34 | AG15: 0.43 | AH15: 40.6 | AI15: 0 | AJ15: 50 | AK15: 1854157 | AL15: 850141
A16: Hungary | B16: Belgium | C16: 2.32 | D16: 2008 | E16: Exports & Imports | F16: 901 | G16: 2045 | H16: 29.47 | I16: 51.42 | J16: -693900 | K16: 1832948 | L16: 2526848 | M16: 2.32 | N16: 1.69
A17: Hungary | B17: Romania | C17: 2.15 | D17: 2008 | E17: Exports & Imports | F17: 2452 | G17: 1500 | H17: 80.21 | I17: 37.72 | J17: 3398348 | K17: 5739594 | L17: 2341246 | M17: 2.15 | N17: 5.3
A18: Hungary | B18: North America | C18: 2.02 | D18: 2008 | E18: Exports & Imports | F18: 1155 | G18: 2155 | H18: 37.78 | I18: 54.19 | J18: 495611 | K18: 2695194 | L18: 2199583 | M18: 2.02 | N18: 2.49 | O18: 3.73 | P18: 1.53 | Q18: 10187 | R18: 66.49 | S18: 29.32 | T18: 1.16 | U18: 3.03 | V18: 174.79 | W18: 0 | X18: 19345 | Y18: 1061612 | Z18: 1092760 | AA18: 3.9 | AB18: 1.53 | AC18: 7467 | AD18: 66.81 | AE18: 28.61 | AF18: 0.75 | AG18: 2.61 | AH18: 174.79 | AI18: 0 | AJ18: 19345 | AK18: 1061612 | AL18: 1092760
A19: Hungary | B19: United Kingdom | C19: 1.95 | D19: 2008 | E19: Exports & Imports | F19: 973 | G19: 2101 | H19: 31.83 | I19: 52.83 | J19: 2935588 | K19: 5055838 | L19: 2120250 | M19: 1.95 | N19: 4.67
A20: Hungary | B20: Other Asia, nes | C20: 1.8 | D20: 2008 | E20: Exports & Imports | J20: -1901035 | K20: 61321 | L20: 1962356 | M20: 1.8 | N20: 0.06
A21: Hungary | B21: United States | C21: 1.8 | D21: 2008 | E21: Exports & Imports | F21: 1086 | G21: 2094 | H21: 35.52 | I21: 52.65 | J21: 515920 | K21: 2478477 | L21: 1962557 | M21: 1.8 | N21: 2.29 | O21: 3.88 | P21: 1.56 | Q21: 7333 | R21: 66.89 | S21: 28.49 | T21: 1.02 | U21: 3.6 | V21: 174.79 | W21: 0 | X21: 18895 | Y21: 961302 | Z21: 956742 | AA21: 3.88 | AB21: 1.56 | AC21: 7333 | AD21: 66.89 | AE21: 28.49 | AF21: 1.02 | AG21: 3.6 | AH21: 174.79 | AI21: 0 | AJ21: 18895 | AK21: 961302 | AL21: 956742
A22: Hungary | B22: Korea, Rep. | C22: 1.69 | D22: 2008 | E22: Exports & Imports | F22: 307 | G22: 790 | H22: 10.04 | I22: 19.86 | J22: -1473411 | K22: 366267 | L22: 1839678 | M22: 1.69 | N22: 0.34 | O22: 3.4 | P22: 2.38 | Q22: 3245 | R22: 71.03 | S22: 27.49 | T22: 0.09 | U22: 1.39 | V22: 33.93 | W22: 0 | X22: 292 | Y22: 1343477 | Z22: 493650 | AA22: 3.4 | AB22: 2.38 | AC22: 3245 | AD22: 71.03 | AE22: 27.49 | AF22: 0.09 | AG22: 1.39 | AH22: 33.93 | AI22: 0 | AJ22: 292 | AK22: 1343477 | AL22: 493650
A23: Hungary | B23: Spain | C23: 1.47 | D23: 2008 | E23: Exports & Imports | F23: 737 | G23: 1736 | H23: 24.11 | I23: 43.65 | J23: 1412171 | K23: 3011143 | L23: 1598972 | M23: 1.47 | N23: 2.78
A24: Hungary | B24: Ukraine | C24: 1.44 | D24: 2008 | E24: Exports & Imports | F24: 1748 | G24: 697 | H24: 57.18 | I24: 17.53 | J24: 603619 | K24: 2165828 | L24: 1562209 | M24: 1.44 | N24: 2 | O24: 2.05 | P24: 0.36 | Q24: 2788 | R24: 21.81 | S24: 75.07 | T24: 0.86 | U24: 2.26 | V24: 174.79 | W24: 0 | X24: 35 | Y24: 141730 | Z24: 1334422 | AA24: 4.07 | AB24: 1.02 | AC24: 2788 | AD24: 65.96 | AE24: 30.92 | AF24: 0.86 | AG24: 2.26 | AH24: 174.79 | AI24: 0 | AJ24: 35 | AK24: 415157 | AL24: 1060995
A25: Hungary | B25: Hong Kong, China | C25: 1.2 | D25: 2008 | E25: Exports & Imports | F25: 351 | G25: 1008 | H25: 11.48 | I25: 25.35 | J25: -1076190 | K25: 230230 | L25: 1306420 | M25: 1.2 | N25: 0.21 | O25: 3.87 | P25: 1.68 | Q25: 3453 | R25: 72.84 | S25: 26.38 | T25: 0.17 | U25: 0.61 | V25: 34.47 | W25: 0 | X25: 2 | Y25: 838120 | Z25: 466123 | AA25: 3.87 | AB25: 1.68 | AC25: 3453 | AD25: 72.84 | AE25: 26.38 | AF25: 0.17 | AG25: 0.61 | AH25: 34.47 | AI25: 0 | AJ25: 2 | AK25: 838120 | AL25: 466123
A26: Hungary | B26: Slovenia | C26: 0.9 | D26: 2008 | E26: Exports & Imports | F26: 1423 | G26: 1252 | H26: 46.55 | I26: 31.48 | J26: 273075 | K26: 1255332 | L26: 982257 | M26: 0.9 | N26: 1.16
A27: Hungary | B27: Switzerland | C27: 0.89 | D27: 2008 | E27: Exports & Imports | F27: 1281 | G27: 1712 | H27: 41.9 | I27: 43.05 | J27: 396277 | K27: 1363649 | L27: 967372 | M27: 0.89 | N27: 1.26 | O27: 0.28 | P27: 0.03 | Q27: 6161 | R27: 1.74 | S27: 96.14 | T27: 0.03 | U27: 2.09 | V27: 174.79 | W27: 0 | X27: 1 | Y27: 3706 | Z27: 957114 | AA27: 4.01 | AB27: 1.34 | AC27: 6161 | AD27: 67.08 | AE27: 27.66 | AF27: 1.3 | AG27: 3.96 | AH27: 174.79 | AI27: 0 | AJ27: 2899 | AK27: 367208 | AL27: 593612
A28: Hungary | B28: Sweden | C28: 0.88 | D28: 2008 | E28: Exports & Imports | F28: 732 | G28: 1187 | H28: 23.95 | I28: 29.85 | J28: 142853 | K28: 1100585 | L28: 957732 | M28: 0.88 | N28: 1.02
A29: Hungary | B29: Finland | C29: 0.76 | D29: 2008 | E29: Exports & Imports | F29: 491 | G29: 735 | H29: 16.06 | I29: 18.48 | J29: -277058 | K29: 549499 | L29: 826557 | M29: 0.76 | N29: 0.51
A30: Hungary | B30: Singapore | C30: 0.73 | D30: 2008 | E30: Exports & Imports | F30: 277 | G30: 385 | H30: 9.06 | I30: 9.68 | J30: -586857 | K30: 210892 | L30: 797749 | M30: 0.73 | N30: 0.19 | O30: 2.73 | P30: 0.4 | Q30: 1757 | R30: 70.18 | S30: 28.91 | T30: 0.28 | U30: 0.63 | V30: 29.16 | W30: 0 | X30: 79 | Y30: 163026 | Z30: 633988 | AA30: 2.73 | AB30: 0.4 | AC30: 1757 | AD30: 70.18 | AE30: 28.91 | AF30: 0.28 | AG30: 0.63 | AH30: 29.16 | AI30: 0 | AJ30: 79 | AK30: 163026 | AL30: 633988
A31: Hungary | B31: Denmark | C31: 0.7 | D31: 2008 | E31: Exports & Imports | F31: 592 | G31: 1110 | H31: 19.37 | I31: 27.91 | J31: 22120 | K31: 778629 | L31: 756509 | M31: 0.7 | N31: 0.72
A32: Hungary | B32: Turkey | C32: 0.55 | D32: 2008 | E32: Exports & Imports | F32: 743 | G32: 1400 | H32: 24.3 | I32: 35.2 | J32: 757958 | K32: 1353370 | L32: 595412 | M32: 0.55 | N32: 1.25 | O32: 0.28 | P32: 0.18 | Q32: 4993 | R32: 0.24 | S32: 93.73 | T32: 1.36 | U32: 4.67 | V32: 174.79 | W32: 0 | X32: 3657 | Y32: 13713 | Z32: 578001 | AA32: 5.01 | AB32: 4.17 | AC32: 4993 | AD32: 73.08 | AE32: 20.39 | AF32: 1.36 | AG32: 5.17 | AH32: 174.79 | AI32: 0 | AJ32: 3657 | AK32: 452855 | AL32: 138859
A33: Hungary | B33: South Asia | C33: 0.53 | D33: 2008 | E33: Exports & Imports | F33: 487 | G33: 899 | H33: 15.93 | I33: 22.61 | J33: -329418 | K33: 243102 | L33: 572520 | M33: 0.53 | N33: 0.22 | O33: 3.74 | P33: 2.18 | Q33: 4144 | R33: 59.24 | S33: 37.16 | T33: 0.8 | U33: 2.8 | V33: 174.79 | W33: 0 | X33: 36 | Y33: 317387 | Z33: 252851 | AA33: 4.44 | AB33: 2.3 | AC33: 3415 | AD33: 70.13 | AE33: 27.03 | AF33: 0.41 | AG33: 1.93 | AH33: 174.79 | AI33: 0 | AJ33: 36 | AK33: 325908 | AL33: 244330
A34: Hungary | B34: India | C34: 0.5 | D34: 2008 | E34: Exports & Imports | F34: 411 | G34: 794 | H34: 13.44 | I34: 19.96 | J34: -398587 | K34: 146955 | L34: 545542 | M34: 0.5 | N34: 0.14 | O34: 4.03 | P34: 1.91 | Q34: 3111 | R34: 68.27 | S34: 28.77 | T34: 0.55 | U34: 2.41 | V34: 174.79 | W34: 0 | X34: 18 | Y34: 303784 | Z34: 239737 | AA34: 4.03 | AB34: 1.91 | AC34: 3111 | AD34: 68.27 | AE34: 28.77 | AF34: 0.55 | AG34: 2.41 | AH34: 174.79 | AI34: 0 | AJ34: 18 | AK34: 303784 | AL34: 239737
A35: Hungary | B35: Malaysia | C35: 0.43 | D35: 2008 | E35: Exports & Imports | F35: 181 | G35: 357 | H35: 5.92 | I35: 8.98 | J35: -427476 | K35: 40279 | L35: 467755 | M35: 0.43 | N35: 0.04 | O35: 1.05 | P35: 0.42 | Q35: 1725 | R35: 18.78 | S35: 79.71 | T35: 0.99 | U35: 0.52 | V35: 25.66 | W35: 0 | X35: 325 | Y35: 70304 | Z35: 394332 | AA35: 3.13 | AB35: 1.62 | AC35: 1725 | AD35: 68.35 | AE35: 30.03 | AF35: 0.99 | AG35: 0.64 | AH35: 29.16 | AI35: 0 | AJ35: 325 | AK35: 214300 | AL35: 250336
A36: Hungary | B36: Ireland | C36: 0.39 | D36: 2008 | E36: Exports & Imports | F36: 318 | G36: 442 | H36: 10.4 | I36: 11.11 | J36: 15838 | K36: 438787 | L36: 422949 | M36: 0.39 | N36: 0.41
A37: Hungary | B37: Croatia | C37: 0.36 | D37: 2008 | E37: Exports & Imports | F37: 1963 | G37: 810 | H37: 64.21 | I37: 20.37 | J37: 1314379 | K37: 1706556 | L37: 392177 | M37: 0.36 | N37: 1.58
A38: Hungary | B38: Latin America & Caribbean | C38: 0.33 | D38: 2008 | E38: Exports & Imports | F38: 643 | G38: 608 | H38: 21.03 | I38: 15.29 | J38: 188864 | K38: 546354 | L38: 357490 | M38: 0.33 | N38: 0.5 | O38: 0.99 | P38: 0.98 | Q38: 4744 | R38: 11.64 | S38: 81.13 | T38: 1.52 | U38: 5.71 | V38: 73.51 | W38: 0 | X38: 1526 | Y38: 48359 | Z38: 288621 | AA38: 4.13 | AB38: 2.43 | AC38: 3002 | AD38: 66.22 | AE38: 23.85 | AF38: 1.08 | AG38: 5.21 | AH38: 74.9 | AI38: 0 | AJ38: 1859 | AK38: 178570 | AL38: 158410
A39: Hungary | B39: Serbia, FR(Serbia/Montenegro) | C39: 0.33 | D39: 2008 | E39: Exports & Imports | F39: 2036 | G39: 791 | H39: 66.6 | I39: 19.89 | J39: 1181446 | K39: 1540510 | L39: 359064 | M39: 0.33 | N39: 1.42 | O39: 4.16 | P39: 15.49 | Q39: 3517 | R39: 65.06 | S39: 26.16 | T39: 2.1 | U39: 6.68 | V39: 174.79 | W39: 0 | X39: 2087 | Y39: 222271 | Z39: 120507 | AA39: 4.16 | AB39: 15.49 | AC39: 3517 | AD39: 65.06 | AE39: 26.16 | AF39: 2.1 | AG39: 6.68 | AH39: 174.79 | AI39: 0 | AJ39: 2087 | AK39: 222271 | AL39: 120507
A40: Hungary | B40: Middle East & North Africa | C40: 0.28 | D40: 2008 | E40: Exports & Imports | F40: 1043 | G40: 905 | H40: 34.12 | I40: 22.76 | J40: 2256108 | K40: 2561114 | L40: 305006 | M40: 0.28 | N40: 2.37 | O40: 1.26 | P40: 0.48 | Q40: 6196 | R40: 10.44 | S40: 79.86 | T40: 1.65 | U40: 8.05 | V40: 93.85 | W40: 0 | X40: 873 | Y40: 20170 | Z40: 269217 | AA40: 5.03 | AB40: 3.09 | AC40: 4229 | AD40: 66.47 | AE40: 21.73 | AF40: 1.26 | AG40: 6.79 | AH40: 93.85 | AI40: 0 | AJ40: 874 | AK40: 202556 | AL40: 86831
...

Sheet EUshare
A1: EU Import share
A2: 1992 | B2: =Partner1992!D4+Partner1992!D6+Partner1992!D7+Partner1992!D12+Partner1992!D13+Partner1992!D15+Partner1992!D17+Partner1992!D18+Partner1992!D23+Partner1992!D25+Partner1992!D26+Partner1992!D36+Partner1992!D43+Partner1992!D54 -> 60.53
A3: 2001 | B3: =Partner2001!C4+Partner2001!C6+Partner2001!C7+Partner2001!C9+Partner2001!C14+Partner2001!C16+Partner2001!C18+Partner2001!C19+Partner2001!C28+Partner2001!C29+Partner2001!C33+Partner2001!C34+Partner2001!C43+Partner2001!C51+Partner2001!C59 -> 57.8
A4: 2008 | B4: =Partner2008!C4+Partner2008!C7+Partner2008!C9+Partner2008!C10+Partner2008!C11+Partner2008!C16+Partner2008!C19+Partner2008!C23+Partner2008!C28+Partner2008!C29+Partner2008!C31 -> 52.89

Sheet Import_tariff_EU
A1: Selected Nomen | B1: Native Nomen | C1: Reporter | D1: Reporter Name | E1: Product | F1: Product Name | G1: Partner | H1: Partner Name | I1: Tariff Year | J1: Trade Year | K1: Trade Source | L1: DutyType | M1: Simple Average | N1: Weighted Average | O1: Standard Deviation | P1: Minimum Rate | Q1: Maximum Rate | R1: Nbr of Total Lines | S1: Nbr of DomesticPeaks | T1: Nbr of InternationalPeaks | U1: Imports Value in 1000 USD | V1: Binding Coverage
A2: HS | B2: H0 | C2: 348 | D2: Hungary | E2: Total | F2: Total Trade | H2: All countries All --- All | I2: 1991 | J2: 1991 | K2: TRN | L2: AHS | M2: 12.36 | N2: 10.07 | O2: 10.87 | P2: 0 | Q2: 500 | R2: 56759 | S2: 2460 | T2: 10758 | U2: 11115173
A3: HS | B3: H0 | C3: 348 | D3: Hungary | E3: Total | F3: Total Trade | H3: All countries All --- All | I3: 1993 | J3: 1993 | K3: CMT | L3: AHS | M3: 10.21 | N3: 8.96 | O3: 11.58 | P3: 0 | Q3: 800 | R3: 67175 | S3: 1613 | T3: 7494 | U3: 11376083
A4: HS | B4: H0 | C4: 348 | D4: Hungary | E4: Total | F4: Total Trade | H4: EU15 --- EU15 | I4: 1991 | J4: 1991 | K4: TRN | L4: AHS | M4: 12.66 | N4: 12.34 | O4: 10.62 | P4: 0 | Q4: 150 | R4: 31820 | S4: 1379 | T4: 6207 | U4: 6421851
A5: HS | B5: H0 | C5: 348 | D5: Hungary | E5: Total | F5: Total Trade | H5: EU15 --- EU15 | I5: 1993 | J5: 1993 | K5: CMT | L5: AHS | M5: 10.35 | N5: 10.56 | O5: 9.37 | P5: 0 | Q5: 150 | R5: 31692 | S5: 737 | T5: 3698 | U5: 6512201
A6: HS | B6: H0 | C6: 348 | D6: Hungary | E6: Total | F6: Total Trade | H6: EU25 --- EU25 members --- EU25 | I6: 1991 | J6: 1991 | K6: TRN | L6: AHS | M6: 12.66 | N6: 12.18 | O6: 10.63 | P6: 0 | Q6: 150 | R6: 33151 | S6: 1445 | T6: 6488 | U6: 6644519
A7: HS | B7: H0 | C7: 348 | D7: Hungary | E7: Total | F7: Total Trade | H7: EU25 --- EU25 members --- EU25 | I7: 1993 | J7: 1993 | K7: CMT | L7: AHS | M7: 10.34 | N7: 10.21 | O7: 9.18 | P7: 0 | Q7: 150 | R7: 42074 | S7: 936 | T7: 4735 | U7: 7479712
A8: HS | B8: H0 | C8: 348 | D8: Hungary | E8: Total | F8: Total Trade | H8: EU27 --- EU27 members --- EU27 | I8: 1991 | J8: 1991 | K8: TRN | L8: AHS | M8: 12.68 | N8: 12.16 | O8: 10.64 | P8: 0 | Q8: 150 | R8: 34505 | S8: 1515 | T8: 6783 | U8: 6740106
A9: HS | B9: H0 | C9: 348 | D9: Hungary | E9: Total | F9: Total Trade | H9: EU27 --- EU27 members --- EU27 | I9: 1993 | J9: 1993 | K9: CMT | L9: AHS | M9: 10.36 | N9: 10.16 | O9: 9.25 | P9: 0 | Q9: 150 | R9: 44302 | S9: 1015 | T9: 5009 | U9: 7632251
A10: HS | B10: H0 | C10: 348 | D10: Hungary | E10: Total | F10: Total Trade | H10: EU28 - EU members (excl. UK) --- EU-UK | I10: 1991 | J10: 1991 | K10: TRN | L10: AHS | M10: 12.68 | N10: 12.14 | O10: 10.65 | P10: 0 | Q10: 150 | R10: 31594 | S10: 1385 | T10: 6212 | U10: 6460277
A11: HS | B11: H0 | C11: 348 | D11: Hungary | E11: Total | F11: Total Trade | H11: EU28 - EU members (excl. UK) --- EU-UK | I11: 1993 | J11: 1993 | K11: CMT | L11: AHS | M11: 10.33 | N11: 10.14 | O11: 9.21 | P11: 0 | Q11: 150 | R11: 41134 | S11: 936 | T11: 4657 | U11: 7314124
A12: HS | B12: H1 | C12: 348 | D12: Hungary | E12: Total | F12: Total Trade | H12: All countries All --- All | I12: 1996 | J12: 1996 | K12: CMT | L12: AHS | M12: 10.32 | N12: 8.62 | O12: 14.1 | P12: 0 | Q12: 142.4 | R12: 164373 | S12: 6779 | T12: 23221 | U12: 16042644.016
A13: HS | B13: H1 | C13: 348 | D13: Hungary | E13: Total | F13: Total Trade | H13: All countries All --- All | I13: 1997 | J13: 1997 | K13: CMT | L13: AHS | M13: 5.85 | N13: 4.48 | O13: 14.68 | P13: 0 | Q13: 138.6 | R13: 179820 | S13: 8254 | T13: 18741 | U13: 20918387.016
... A31: HS | B31: H3 | C31: 348 | D31: Hungary | E31: Total | F31: Total Trade | H31: All countries All --- All | I31: 2008 | J31: 2008 | K31: CMT | L31: AHS | M31: 2.07 | N31: 0.93 | O31: 3.59 | P31: 0 | Q31: 57.6 | R31: 83800 | S31: 959 | T31: 819 | U31: 29089151

Sheet Importshares
A1: year | B1: Column1 | C1: import_share_WB
A2: 1991 | B2: =100*C2 -> 29.53255 | C2: 0.2953255
A3: 1992 | B3: =100*C3 -> 27.76957 | C3: 0.2776957
A4: 1993 | B4: =100*C4 -> 30.30694 | C4: 0.3030694
A5: 1994 | B5: =100*C5 -> 30.99572 | C5: 0.3099572
A6: 1995 | B6: =100*C6 -> 39.11579 | C6: 0.3911579
A7: 1996 | B7: =100*C7 -> 41.34083 | C7: 0.4134083
A8: 1997 | B8: =100*C8 -> 46.87738 | C8: 0.4687738
A9: 1998 | B9: =100*C9 -> 54.36175 | C9: 0.5436175
A10: 1999 | B10: =100*C10 -> 58.2079 | C10: 0.582079
A11: 2000 | B11: =100*C11 -> 70.31291 | C11: 0.7031291
A12: 2001 | B12: =100*C12 -> 65.96305 | C12: 0.6596305
A13: 2002 | B13: =100*C13 -> 59.97944 | C13: 0.5997944
... A28: 2017 | B28: =100*C28 -> 82.27032 | C28: 0.8227032

Sheet Foregin credit to NFC
A1: Links | B1: https://fred.stlouisfed.org/series/QHUNAM770A | C1: https://fred.stlouisfed.org/series/QHUPAM770A | D1: https://fred.stlouisfed.org/series/QHUPBM770A
B2: Credit_GDP_NFC | C2: Private to non-financial sector | D2: Domestic Banks to NFC | E2: Foreign ratio | F2: Relevant NFC Foreign credit | G2: Credit_GDP_NFC - no 1990 Foreign credit | H2: Corrected ratio | L2: (a known BIS data break/reclassification when Hungary transitioned to a market economy, that from what I gathered mostly affected the post 1987 Banking Act )
A3: 1970-12-31 | B3: 28.8 | C3: 35.3 | D3: 30 | E3: =(C3-D3)/C3 -> 0.15014164 | F3: 0 | G3: =B3-0 -> 28.8 | H3: =F3/G3 -> 0
A4: 1971-03-31 | B4: 29.6 | C4: 36.2 | D4: 31 | E4: =(C4-D4)/C4 -> 0.14364641 | F4: 0 | G4: =B4-0 -> 29.6 | H4: =F4/G4 -> 0
A5: 1971-06-30 | B5: 30.5 | C5: 37.3 | D5: 32 | E5: =(C5-D5)/C5 -> 0.14209115 | F5: 0 | G5: =B5-0 -> 30.5 | H5: =F5/G5 -> 0
A6: 1971-09-30 | B6: 31.4 | C6: 38.3 | D6: 33.1 | E6: =(C6-D6)/C6 -> 0.13577023 | F6: 0 | G6: =B6-0 -> 31.4 | H6: =F6/G6 -> 0
A7: 1971-12-31 | B7: 32.2 | C7: 39.3 | D7: 34 | E7: =(C7-D7)/C7 -> 0.13486005 | F7: 0 | G7: =B7-0 -> 32.2 | H7: =F7/G7 -> 0
A8: 1972-03-31 | B8: 32 | C8: 39.1 | D8: 33.8 | E8: =(C8-D8)/C8 -> 0.13554987 | F8: 0 | G8: =B8-0 -> 32 | H8: =F8/G8 -> 0
A9: 1972-06-30 | B9: 31.9 | C9: 39.2 | D9: 33.6 | E9: =(C9-D9)/C9 -> 0.14285714 | F9: 0 | G9: =B9-0 -> 31.9 | H9: =F9/G9 -> 0
A10: 1972-09-30 | B10: 31.7 | C10: 39.2 | D10: 33.4 | E10: =(C10-D10)/C10 -> 0.14795918 | F10: 0 | G10: =B10-0 -> 31.7 | H10: =F10/G10 -> 0
A11: 1972-12-31 | B11: 31.5 | C11: 39.1 | D11: 33.1 | E11: =(C11-D11)/C11 -> 0.15345269 | F11: 0 | G11: =B11-0 -> 31.5 | H11: =F11/G11 -> 0
A12: 1973-03-31 | B12: 31.6 | C12: 39.2 | D12: 32.9 | E12: =(C12-D12)/C12 -> 0.16071429 | F12: 0 | G12: =B12-0 -> 31.6 | H12: =F12/G12 -> 0
A13: 1973-06-30 | B13: 31.5 | C13: 39.3 | D13: 32.5 | E13: =(C13-D13)/C13 -> 0.17302799 | F13: 0 | G13: =B13-0 -> 31.5 | H13: =F13/G13 -> 0
A14: 1973-09-30 | B14: 31.5 | C14: 39.4 | D14: 32.1 | E14: =(C14-D14)/C14 -> 0.18527919 | F14: 0 | G14: =B14-0 -> 31.5 | H14: =F14/G14 -> 0
... A67: 1986-12-31 | B67: 46.6 | C67: 66.6 | D67: 47.7 | E67: =(C67-D67)/C67 -> 0.28378378 | F67: 0 | G67: =B67-0 -> 46.6 | H67: =F67/G67 -> 0
A68: 1987-03-31 | B68: 47.1 | C68: 67.2 | D68: 48.1 | E68: =(C68-D68)/C68 -> 0.28422619 | F68: =B68*E68-$E$67*$B$67 -> 0.16272925 | G68: =B68-$E$67*$B$67 -> 33.875676 | H68: =F68/G68 -> 0.0048037196
A69: 1987-06-30 | B69: 46.8 | C69: 67.2 | D69: 48 | E69: =(C69-D69)/C69 -> 0.28571429 | F69: =B69*E69-$E$67*$B$67 -> 0.14710425 | G69: =B69-$E$67*$B$67 -> 33.575676 | H69: =F69/G69 -> 0.0043812744
A70: 1987-09-30 | B70: 46.5 | C70: 67 | D70: 47.9 | E70: =(C70-D70)/C70 -> 0.28507463 | F70: =B70*E70-$E$67*$B$67 -> 0.031645825 | G70: =B70-$E$67*$B$67 -> 33.275676 | H70: =F70/G70 -> 0.00095101976
A71: 1987-12-31 | B71: 46.8 | C71: 67.4 | D71: 48 | E71: =(C71-D71)/C71 -> 0.28783383 | F71: =B71*E71-$E$67*$B$67 -> 0.24629882 | G71: =B71-$E$67*$B$67 -> 33.575676 | H71: =F71/G71 -> 0.0073356326
A72: 1988-03-31 | B72: 45.9 | C72: 66.3 | D72: 46.4 | E72: =(C72-D72)/C72 -> 0.30015083 | F72: =B72*E72-$E$67*$B$67 -> 0.55259875 | G72: =B72-$E$67*$B$67 -> 32.675676 | H72: =F72/G72 -> 0.016911624
A73: 1988-06-30 | B73: 45.1 | C73: 65.4 | D73: 45.7 | E73: =(C73-D73)/C73 -> 0.30122324 | F73: =B73*E73-$E$67*$B$67 -> 0.36084387 | G73: =B73-$E$67*$B$67 -> 31.875676 | H73: =F73/G73 -> 0.011320352
A74: 1988-09-30 | B74: 44.7 | C74: 65.1 | D74: 45.3 | E74: =(C74-D74)/C74 -> 0.30414747 | F74: =B74*E74-$E$67*$B$67 -> 0.37106738 | G74: =B74-$E$67*$B$67 -> 31.475676 | H74: =F74/G74 -> 0.01178902
A75: 1988-12-31 | B75: 44.7 | C75: 64.7 | D75: 44.6 | E75: =(C75-D75)/C75 -> 0.31066461 | F75: =B75*E75-$E$67*$B$67 -> 0.66238356 | G75: =B75-$E$67*$B$67 -> 31.475676 | H75: =F75/G75 -> 0.0210443
A76: 1989-03-31 | B76: 46.3 | C76: 66 | D76: 46 | E76: =(C76-D76)/C76 -> 0.3030303 | F76: =B76*E76-$E$67*$B$67 -> 0.80597871 | G76: =B76-$E$67*$B$67 -> 33.075676 | H76: =F76/G76 -> 0.024367717
A77: 1989-06-30 | B77: 46.1 | C77: 65.8 | D77: 46 | E77: =(C77-D77)/C77 -> 0.30091185 | F77: =B77*E77-$E$67*$B$67 -> 0.64771215 | G77: =B77-$E$67*$B$67 -> 32.875676 | H77: =F77/G77 -> 0.019701866
A78: 1989-09-30 | B78: 47 | C78: 66.6 | D78: 47.3 | E78: =(C78-D78)/C78 -> 0.28978979 | F78: =B78*E78-$E$67*$B$67 -> 0.3957958 | G78: =B78-$E$67*$B$67 -> 33.775676 | H78: =F78/G78 -> 0.011718368
A79: 1989-12-31 | B79: 43 | C79: 61.1 | D79: 42.6 | E79: =(C79-D79)/C79 -> 0.30278232 | F79: =B79*E79-$E$67*$B$67 -> -0.20468439 | G79: =B79-$E$67*$B$67 -> 29.775676 | H79: =F79/G79 -> -0.0068742148
... A152: 2008-03-31 | B152: 78.6 | C152: 110.8 | D152: 53.8 | E152: =(C152-D152)/C152 -> 0.51444043 | F152: =B152*E152-$E$67*$B$67 -> 27.210694 | G152: =B152-$E$67*$B$67 -> 65.375676 | H152: =F152/G152 -> 0.41622046
A153: 2008-06-30 | B153: 74.5 | C153: 105.4 | D153: 51.2 | E153: =(C153-D153)/C153 -> 0.5142315 | F153: =B153*E153-$E$67*$B$67 -> 25.085922 | G153: =B153-$E$67*$B$67 -> 61.275676 | H153: =F153/G153 -> 0.40939446 | I153: This is the quarter before the crisis
A154: 2008-09-30 | B154: 77.8 | C154: 110.8 | D154: 54.3 | E154: =(C154-D154)/C154 -> 0.5099278 | F154: =B154*E154-$E$67*$B$67 -> 26.448058 | G154: =B154-$E$67*$B$67 -> 64.575676 | H154: =F154/G154 -> 0.40956689
A155: 2008-12-31 | B155: 81 | C155: 117.6 | D155: 58.1 | E155: =(C155-D155)/C155 -> 0.50595238 | F155: =B155*E155-$E$67*$B$67 -> 27.757819 | G155: =B155-$E$67*$B$67 -> 67.775676 | H155: =F155/G155 -> 0.40955429
A156: 2009-03-31 | B156: 94.9 | C156: 135.6 | D156: 64.4 | E156: =(C156-D156)/C156 -> 0.52507375 | F156: =B156*E156-$E$67*$B$67 -> 36.605174 | G156: =B156-$E$67*$B$67 -> 81.675676 | H156: =F156/G156 -> 0.44817718
A157: 2009-06-30 | B157: 88.7 | C157: 126.3 | D157: 59.5 | E157: =(C157-D157)/C157 -> 0.52889945 | F157: =B157*E157-$E$67*$B$67 -> 33.689057 | G157: =B157-$E$67*$B$67 -> 75.475676 | H157: =F157/G157 -> 0.44635647
A158: 2009-09-30 | B158: 87.5 | C158: 125.2 | D158: 59.3 | E158: =(C158-D158)/C158 -> 0.52635783 | F158: =B158*E158-$E$67*$B$67 -> 32.831986 | G158: =B158-$E$67*$B$67 -> 74.275676 | H158: =F158/G158 -> 0.44202877
A159: 2009-12-31 | B159: 91.5 | C159: 129.4 | D159: 58.9 | E159: =(C159-D159)/C159 -> 0.54482226 | F159: =B159*E159-$E$67*$B$67 -> 36.626912 | G159: =B159-$E$67*$B$67 -> 78.275676 | H159: =F159/G159 -> 0.46792202
A160: 2010-03-31 | B160: 90.7 | C160: 128.7 | D160: 58.5 | E160: =(C160-D160)/C160 -> 0.54545455 | F160: =B160*E160-$E$67*$B$67 -> 36.248403 | G160: =B160-$E$67*$B$67 -> 77.475676 | H160: =F160/G160 -> 0.46786817
A161: 2010-06-30 | B161: 94.2 | C161: 135.4 | D161: 61.8 | E161: =(C161-D161)/C161 -> 0.54357459 | F161: =B161*E161-$E$67*$B$67 -> 37.980402 | G161: =B161-$E$67*$B$67 -> 80.975676 | H161: =F161/G161 -> 0.46903471
A162: 2010-09-30 | B162: 88.4 | C162: 127.6 | D162: 59.3 | E162: =(C162-D162)/C162 -> 0.53526646 | F162: =B162*E162-$E$67*$B$67 -> 34.093231 | G162: =B162-$E$67*$B$67 -> 75.175676 | H162: =F162/G162 -> 0.45351412
A163: 2010-12-31 | B163: 86.5 | C163: 126.3 | D163: 59.4 | E163: =(C163-D163)/C163 -> 0.52969121 | F163: =B163*E163-$E$67*$B$67 -> 32.593965 | G163: =B163-$E$67*$B$67 -> 73.275676 | H163: =F163/G163 -> 0.4448129
A164: 2011-03-31 | B164: 83 | C164: 119.8 | D164: 55.5 | E164: =(C164-D164)/C164 -> 0.53672788 | F164: =B164*E164-$E$67*$B$67 -> 31.32409 | G164: =B164-$E$67*$B$67 -> 69.775676 | H164: =F164/G164 -> 0.44892564
...

Sheet Real exchange rate
C1: Hungary REER | E1: Renormalized | G1: Real Broad Effective Exchange Rate for Hungary (RBHUBIS)
B2: 34335 | C2: 85.3 | E2: =C2/$C$89 -> 0.97352203
B3: 34366 | C3: 84.33 | E3: =C3/$C$89 -> 0.9624515
B4: 34394 | C4: 83.69 | E4: =C4/$C$89 -> 0.95514723
B5: 34425 | C5: 84.46 | E5: =C5/$C$89 -> 0.96393517
B6: 34455 | C6: 84.32 | E6: =C6/$C$89 -> 0.96233737
B7: 34486 | C7: 83.67 | E7: =C7/$C$89 -> 0.95491897
B8: 34516 | C8: 83.92 | E8: =C8/$C$89 -> 0.9577722
B9: 34547 | C9: 79.55 | E9: =C9/$C$89 -> 0.90789774
B10: 34578 | C10: 79.94 | E10: =C10/$C$89 -> 0.91234878
B11: 34608 | C11: 81.01 | E11: =C11/$C$89 -> 0.9245606
B12: 34639 | C12: 81.62 | E12: =C12/$C$89 -> 0.93152248
B13: 34669 | C13: 82.05 | E13: =C13/$C$89 -> 0.93643004
... B377: 45748 | C377: 108.23 | E377: =C377/$C$89 -> 1.2352203

Sheet Hungary Macro-facts
B3: GDP | C3: German GDP | D3: Hungary Savings rate | E3: Domestic saving rate | F3: EU GDP PPP per capita
A4: 1990 | B4: 9133.1414 | F4: 14969.244 | K4: German growth from 1991 | O4: Hungary Growth from 1991 to 2008
A5: 1991 | B5: 8319.6312 | C5: 21058.077 | D5: 19.231289 | E5: 20.09358 | F5: 15561.193 | K5: =C22/C5-1 -> 0.82559591 | O5: =B22/B5 - 1 -> 1.4906756
A6: 1992 | B6: 8251.7195 | C6: 21806.21 | D6: 15.97877 | E6: 16.444505 | F6: 15975.576 | O6: Hungary Growth from 1991 to 2001
A7: 1993 | B7: 8408.2302 | C7: 21940.162 | D7: 11.878287 | E7: 12.419275 | F7: 16202.42 | O7: =B15/B5 - 1 -> 0.58803038
A8: 1994 | B8: 8852.9869 | C8: 22886.768 | D8: 15.696838 | E8: 16.354209 | F8: 16950.265 | H8: GDP per capita comparisons | M8: Savings rate from peak to trough
A9: 1995 | B9: 9186.0376 | C9: 23614.958 | D9: 19.334844 | E9: 23.138387 | F9: 17754.594 | I9: relative to Gerrmany | J9: relative to EU
A10: 1996 | B10: 9349.0138 | C10: 24160.067 | D10: 20.751594 | E10: 25.282405 | F10: 18349.809 | H10: 1991 | I10: =B5/C5 -> 0.3950803 | J10: =B5/F5 -> 0.53463969 | M10: 12% to 27%
A11: 1997 | B11: 9823.0258 | C11: 24643.683 | D11: 21.503298 | E11: 27.243836 | F11: 19070.095 | H11: 2001 | I11: =B15/C15 -> 0.46070855 | J11: =B15/F15 -> 0.56918649
A12: 1998 | B12: 10398.029 | C12: 25444.151 | D12: 21.345411 | E12: 27.145834 | F12: 19968.036 | H12: 2008 | I12: =B22/C22 -> 0.53901132 | J12: =B22/F22 -> 0.6351337
A13: 1999 | B13: 10873.248 | C13: 26517.934 | D13: 18.709648 | E13: 24.425674 | F13: 20767.773
A14: 2000 | B14: 11854.683 | C14: 27467.782 | D14: 19.251435 | E14: 24.374079 | F14: 22106.381
A15: 2001 | B15: 13211.827 | C15: 28677.191 | D15: 19.773596 | E15: 24.944788 | F15: 23211.772
A16: 2002 | B16: 14526.388 | C16: 29513.682 | D16: 18.543711 | E16: 23.557257 | F16: 24229.643 | K16: Wages Hungary | N16: Normalized
A17: 2003 | B17: 15479.101 | C17: 30305.258 | D17: 15.785717 | E17: 20.67199 | F17: 24762.903 | K17: 2001 | L17: 38.358 | N17: 100
A18: 2004 | B18: 16269.309 | C18: 31757.418 | D18: 16.696465 | E18: 23.063176 | F18: 25929.074 | K18: 2008 | L18: 69.574 | N18: =L18/L17 -> 1.8138068
A19: 2005 | B19: 17108.341 | C19: 32313.737 | D19: 16.57385 | E19: 23.188935 | F19: 26906.315
A20: 2006 | B20: 18383.632 | C20: 34748.754 | D20: 18.081168 | E20: 24.780828 | F20: 29244.406
A21: 2007 | B21: 19098.626 | C21: 36915.325 | D21: 16.764686 | E21: 24.963082 | F21: 31162.91 | K21: Adjusted for inflation | N21: =N18/(1+Inflation!C42/100)/(1+Inflation!C43/100)/(1+Inflation!C44/100)/(1+Inflation!C45/100)/(1+Inflation!C46/100)/(1+Inflation!C47/100)/(1+Inflation!C48/100)/(1+Inflation!C49/100) -> 1.4380517
A22: 2008 | B22: 20721.502 | C22: 38443.539 | D22: 17.773422 | E22: 25.101365 | F22: 32625.418
A23: 2009 | B23: 20722.065 | C23: 37554.443 | D23: 19.794322 | E23: 24.507258 | F23: 31983.937
A24: 2010 | B24: 21738.897 | C24: 39730.49 | D24: 20.785447 | E24: 25.934014 | F24: 33055.686
A25: 2011 | B25: 23029.447 | C25: 43398.344 | D25: 21.00328 | E25: 26.516162 | F25: 34733.959
A26: 2012 | B26: 23267.448 | C26: 44229.394 | D26: 21.132868 | E26: 26.270876 | F26: 35181.63
A27: 2013 | B27: 24547.981 | C27: 45889.017 | D27: 24.55524 | E27: 28.095385 | F27: 36304.696
A28: 2014 | B28: 25691.527 | C28: 47938.797 | D28: 24.623878 | E28: 29.907845 | F28: 37327.194
A29: 2015 | B29: 26806.045 | C29: 48558.443 | D29: 25.391992 | E29: 31.244766 | F29: 38512.787
A30: 2016 | B30: 27941.927 | C30: 51569.902 | D30: 25.773197 | E30: 29.954111 | F30: 40844.429
A31: 2017 | B31: 29496.164 | C31: 54110.254 | D31: 24.722459 | E31: 29.713862 | F31: 42966.669
A32: 2018 | B32: 31908.863 | C32: 56273.041 | D32: 26.79269 | E32: 31.059315 | F32: 44965.823
A33: 2019 | B33: 35152.604 | C33: 59270.728 | D33: 27.472152 | E33: 30.701075 | F33: 48546.645
... A37: 2023 | B37: 45021.301 | C37: 69205.883 | D37: 25.777703 | E37: 30.457844 | F37: 59044.973
A38: 2024

Sheet Hungary Imports
A1: Import tariff revenue | D1: Import value | G1: current LCU | K1: Implied tariff rate | N1: Summarized in https://www.ksh.hu/statszemle_archive/1997/1997_01/1997_01_045.pdf
N2: Can even go back to 1988, this one is until 1995, table 3
A3: 1990 | B3: 52400000000 | N3: Slight differences relative to the article because these are the official numbers from a website that has been made unavailable since then
A4: 1991 | B4: 62800000000 | E4: 768628466000 | K4: =B4/E4 -> 0.081703974
A5: 1992 | B5: 100200000000 | E5: 851291234000 | K5: =B5/E5 -> 0.11770355
A6: 1993 | B6: 128200000000 | E6: 1120277037000 | K6: =B6/E6 -> 0.11443598
A7: 1994 | B7: 150500000000 | E7: 1409401974000 | K7: =B7/E7 -> 0.10678288
A8: 1995 | B8: 249431000000 | E8: 2287681000000 | K8: =B8/E8 -> 0.10903225
A9: 1996 | B9: 248709000000 | E9: 2949305000000 | K9: =B9/E9 -> 0.084328003
A10: 1997 | B10: 161300000000 | E10: 4147234000000 | K10: =B10/E10 -> 0.038893393
A11: 1998 | B11: 131593000000 | E11: 5691306000000 | K11: =B11/E11 -> 0.023121758
A12: 1999 | B12: 141082000000 | E12: 6794246000000 | K12: =B12/E12 -> 0.020764924
A13: 2000 | B13: 137731000000 | E13: 9399947000000 | K13: =B13/E13 -> 0.014652317
A14: 2001 | B14: 125013000000 | E14: 10188973000000 | K14: =B14/E14 -> 0.012269441
A15: 2002 | B15: 129341000000 | E15: 10492243000000 | K15: =B15/E15 -> 0.012327297
A16: 2003 | B16: 132638000000 | E16: 11532525000000 | K16: =B16/E16 -> 0.011501211

Sheet Hungary TFP
B1: TFP | C1: TFP new base
A2: 1991 | B2: 0.7899068 | C2: =B2/$B$2 -> 1 | H2: Current price, from FRED
A3: 1992 | B3: 0.81926131 | C3: =B3/$B$2 -> 1.037162
A4: 1993 | B4: 0.84526825 | C4: =B4/$B$2 -> 1.0700861
A5: 1994 | B5: 0.84284204 | C5: =B5/$B$2 -> 1.0670145
A6: 1995 | B6: 0.85724908 | C6: =B6/$B$2 -> 1.0852535
A7: 1996 | B7: 0.85105383 | C7: =B7/$B$2 -> 1.0774104
A8: 1997 | B8: 0.85897702 | C8: =B8/$B$2 -> 1.087441
A9: 1998 | B9: 0.87395144 | C9: =B9/$B$2 -> 1.1063982
A10: 1999 | B10: 0.86976105 | C10: =B10/$B$2 -> 1.1010933
A11: 2000 | B11: 0.89250225 | C11: =B11/$B$2 -> 1.129883
A12: 2001 | B12: 0.9183045 | C12: =B12/$B$2 -> 1.1625479
A13: 2002 | B13: 0.94671416 | C13: =B13/$B$2 -> 1.1985138
A14: 2003 | B14: 0.96270871 | C14: =B14/$B$2 -> 1.2187624
... A19: 2008 | B19: 1.0457413 | C19: =B19/$B$2 -> 1.3238794
A20: 2009 | B20: 0.98531854
A21: 2010 | B21: 0.98756135
A22: 2011 | B22: 1.0024757
A23: 2012 | B23: 0.98101777
A24: 2013 | B24: 0.98400229
A25: 2014 | B25: 0.98199743
A26: 2015 | B26: 0.99385798
A27: 2016 | B27: 0.98001379
A28: 2017 | B28: 1
A29: 2018 | B29: 1.0274681
A30: 2019 | B30: 1.0431733
A31: 2020
A32: 2021
A33: 2022
A34: 2023
A35: 2024

Sheet Hungary Consumption
B1: Hungary Cons | D1: 1991 base
A2: 1991 | B2: 0.7899068 | D2: =B2/$B$2 -> 1 | F2: National Accounts: GDP by Expenditure: Current Prices: Private Final Consumption Expenditure for Hungary (HUNPFCEADSMEI)
A3: 1992 | B3: 0.81926131 | D3: =B3/$B$2 -> 1.037162
A4: 1993 | B4: 0.84526825 | D4: =B4/$B$2 -> 1.0700861
A5: 1994 | B5: 0.84284204 | D5: =B5/$B$2 -> 1.0670145
A6: 1995 | B6: 0.85724908 | D6: =B6/$B$2 -> 1.0852535
A7: 1996 | B7: 0.85105383 | D7: =B7/$B$2 -> 1.0774104
A8: 1997 | B8: 0.85897702 | D8: =B8/$B$2 -> 1.087441
A9: 1998 | B9: 0.87395144 | D9: =B9/$B$2 -> 1.1063982
A10: 1999 | B10: 0.86976105 | D10: =B10/$B$2 -> 1.1010933
A11: 2000 | B11: 0.89250225 | D11: =B11/$B$2 -> 1.129883
A12: 2001 | B12: 0.9183045 | D12: =B12/$B$2 -> 1.1625479
A13: 2002 | B13: 0.94671416 | D13: =B13/$B$2 -> 1.1985138
A14: 2003 | B14: 0.96270871 | D14: =B14/$B$2 -> 1.2187624
... A30: 2019 | B30: 1.0431733 | D30: =B30/$B$2 -> 1.3206283

Sheet Hungary Capital
B1: Capital | C1: with 1991
A2: 1970 | B2: 264960.91 | C2: =B2/$B$23 -> 0.36339812 | K2: Capital Stock at Constant National Prices for Hungary (RKNANPHUA666NRUG)
A3: 1971 | B3: 292100.53 | C3: =B3/$B$23 -> 0.40062055
A4: 1972 | B4: 316554.16 | C4: =B4/$B$23 -> 0.43415909
A5: 1973 | B5: 340340.59 | C5: =B5/$B$23 -> 0.46678257
A6: 1974 | B6: 366926.19 | C6: =B6/$B$23 -> 0.50324514
A7: 1975 | B7: 396781.62 | C7: =B7/$B$23 -> 0.54419235
A8: 1976 | B8: 424577.03 | C8: =B8/$B$23 -> 0.58231419
A9: 1977 | B9: 456782.81 | C9: =B9/$B$23 -> 0.62648493
A10: 1978 | B10: 489812.94 | C10: =B10/$B$23 -> 0.67178628
A11: 1979 | B11: 521105.78 | C11: =B11/$B$23 -> 0.71470491
A12: 1980 | B12: 547018.12 | C12: =B12/$B$23 -> 0.75024411
A13: 1981 | B13: 569271.12 | C13: =B13/$B$23 -> 0.78076445
A14: 1982 | B14: 589707.94 | C14: =B14/$B$23 -> 0.80879387
... A51: 2019 | B51: 1367535.8 | C51: =B51/$B$23 -> 1.8755972

Sheet Lending rate raw
A1: Column1 | B1: Column2 | C1: Column3 | D1: Column4 | E1: Column5 | F1: Column6 | G1: Column7 | H1: Column8 | I1: Column9 | J1: Column10 | K1: Column11 | L1: Column12 | M1: Column13 | N1: Column14 | O1: Column15 | P1: Column16 | Q1: Column17 | R1: Column18 | S1: Column19 | T1: Column20 | U1: Column21 | V1: Column22 | W1: Column23 | X1: Column24 | Y1: Column25 | Z1: Column26 | AA1: Column27 | AB1: Column28 | AC1: Column29 | AD1: Column30 | AE1: Column31 | AF1: Column32 | AG1: Column33 | AH1: Column34 | AI1: Column35 | AJ1: Column36 | AK1: Column37 | AL1: Column38 | AM1: Column39 | AN1: Column40 | AO1: Column41 | AP1: Column42 | AQ1: Column43 | AR1: Column44 | AS1: Column45 | AT1: Column46 | AU1: Column47 | AV1: Column48 | AW1: Column49 | AX1: Column50 | AY1: Column51 | AZ1: Column52 | BA1: Column53 | BB1: Column54 | BC1: Column55 | BD1: Column56 | BE1: Column57 | BF1: Column58 | BG1: Column59 | BH1: Column60 | BI1: Column61 | BJ1: Column62 | BK1: Column63 | BL1: Column64 | BM1: Column65 | BN1: Column66 | BO1: Column67 | BP1: Column68 | BQ1: Column69 | BR1: Column70
A2: Data Source | B2: World Development Indicators
A4: Last Updated Date | B4: 2025-04-15
A6: Country Name | B6: Country Code | C6: Indicator Name | D6: Indicator Code | E6: 1960 | F6: 1961 | G6: 1962 | H6: 1963 | I6: 1964 | J6: 1965 | K6: 1966 | L6: 1967 | M6: 1968 | N6: 1969 | O6: 1970 | P6: 1971 | Q6: 1972 | R6: 1973 | S6: 1974 | T6: 1975 | U6: 1976 | V6: 1977 | W6: 1978 | X6: 1979 | Y6: 1980 | Z6: 1981 | AA6: 1982 | AB6: 1983 | AC6: 1984 | AD6: 1985 | AE6: 1986 | AF6: 1987 | AG6: 1988 | AH6: 1989 | AI6: 1990 | AJ6: 1991 | AK6: 1992 | AL6: 1993 | AM6: 1994 | AN6: 1995 | AO6: 1996 | AP6: 1997 | AQ6: 1998 | AR6: 1999 | AS6: 2000 | AT6: 2001 | AU6: 2002 | AV6: 2003 | AW6: 2004 | AX6: 2005 | AY6: 2006 | AZ6: 2007 | BA6: 2008 | BB6: 2009 | BC6: 2010 | BD6: 2011 | BE6: 2012 | BF6: 2013 | BG6: 2014 | BH6: 2015 | BI6: 2016 | BJ6: 2017 | BK6: 2018 | BL6: 2019 | BM6: 2020 | BN6: 2021 | BO6: 2022 | BP6: 2023 | BQ6: 2024
A7: Aruba | B7: ABW | C7: Lending interest rate (%) | D7: FR.INR.LEND | AE7: 11 | AF7: 10.3 | AG7: 10.2416666666667 | AH7: 10.475 | AI7: 10.6 | AJ7: 10.675 | AK7: 10.6 | AL7: 10.6 | AM7: 10.6 | AN7: 10.6 | AO7: 10.375 | AP7: 10.25 | AQ7: 11.0416666666667 | AR7: 13.1416666666667 | AS7: 12.0666666666667 | AT7: 12.6 | AU7: 11.3 | AV7: 10.7 | AW7: 9.6 | AX7: 11 | AY7: 9.5 | AZ7: 10.4 | BA7: 10.5 | BB7: 10.7 | BC7: 10.3 | BD7: 9 | BE7: 8.4 | BF7: 8.5 | BG7: 7.3 | BH7: 7 | BI7: 6.9 | BJ7: 6.3 | BK7: 6 | BL7: 5.7 | BM7: 6.8 | BN7: 6.4 | BO7: 6.1 | BP7: 5.8
A8: Africa Eastern and Southern | B8: AFE | C8: Lending interest rate (%) | D8: FR.INR.LEND
A9: Afghanistan | B9: AFG | C9: Lending interest rate (%) | D9: FR.INR.LEND | AY9: 17.97 | AZ9: 18.135 | BA9: 14.9175 | BB9: 15 | BC9: 15.6122222222222 | BD9: 15.1458333333333 | BE9: 15 | BF9: 15.0791666666667 | BG9: 15 | BH9: 15 | BI9: 15 | BJ9: 14.8366666666667
A10: Africa Western and Central | B10: AFW | C10: Lending interest rate (%) | D10: FR.INR.LEND
A11: Angola | B11: AGO | C11: Lending interest rate (%) | D11: FR.INR.LEND | AN11: 206.25 | AO11: 217.875 | AP11: 37.75 | AQ11: 45 | AR11: 80.2966666666667 | AS11: 103.160174166667 | AT11: 95.9665608333333 | AU11: 97.3358333333333 | AV11: 96.115 | AW11: 82.3341666666667 | AX11: 67.7181307369684 | AY11: 19.5108144527911 | AZ11: 17.6988356005955 | BA11: 12.533605759663 | BB11: 15.682074235437 | BC11: 22.5435720221269 | BD11: 18.7572405365757 | BE11: 16.6564013212232 | BF11: 15.8086382955866 | BG11: 16.3822709411366 | BH11: 16.8818623998822 | BI11: 15.7805039391116 | BJ11: 15.8061003813255 | BK11: 20.6770040277157 | BL11: 19.295367205655 | BM11: 19.6558949254322 | BN11: 19.4031546297083 | BO11: 20.1172113762759 | BP11: 16.9208615225951 | BQ11: 19.3991553172159
A12: Albania | B12: ALB | C12: Lending interest rate (%) | D12: FR.INR.LEND | AE12: 1 | AF12: 1 | AG12: 1 | AH12: 1 | AI12: 1 | AJ12: 1 | AK12: 20.5833333333333 | AL12: 29.5833333333333 | AM12: 23.6666666666667 | AN12: 19.65 | AO12: 23.9583333333333 | AP12: 32.7083333333333 | AR12: 21.615 | AS12: 22.1025 | AT12: 19.6541666666667 | AU12: 15.3041666666667 | AV12: 14.2708333333333 | AW12: 11.7615218344487 | AX12: 13.075 | AY12: 12.9399428618515 | AZ12: 14.0996227871662 | BA12: 13.0196427128802 | BB12: 12.6609351537225 | BC12: 12.8223298853561 | BD12: 12.4320985987679 | BE12: 10.8803465425902 | BF12: 9.8266043443155 | BG12: 7.9725 | BH12: 7.8775 | BI12: 6.73416666666667 | BJ12: 6.22 | BK12: 5.9325 | BL12: 6.27583333333333 | BM12: 6.12083333333333 | BN12: 6.02166666666667 | BO12: 6.50666666666667 | BP12: 6.35166666666667 | BQ12: 6.44333333333333
A13: Andorra | B13: AND | C13: Lending interest rate (%) | D13: FR.INR.LEND
A14: Arab World | B14: ARB | C14: Lending interest rate (%) | D14: FR.INR.LEND
A15: United Arab Emirates | B15: ARE | C15: Lending interest rate (%) | D15: FR.INR.LEND
A16: Argentina | B16: ARG | C16: Lending interest rate (%) | D16: FR.INR.LEND | BC16: 10.5575 | BD16: 14.0875 | BE16: 14.0608333333333 | BF16: 17.1491666666667 | BG16: 24.0091666666667 | BH16: 24.9158333333333 | BI16: 31.2325 | BJ16: 26.5808333333333 | BK16: 48.5166666666667 | BL16: 67.2541666666667 | BM16: 29.3875 | BN16: 35.5583333333333 | BO16: 52.3991666666667 | BP16: 95.8941666666667 | BQ16: 61.7066666666667
A17: Armenia | B17: ARM | C17: Lending interest rate (%) | D17: FR.INR.LEND | AN17: 96.1 | AO17: 66.3583333333333 | AP17: 54.2275 | AQ17: 48.485 | AR17: 38.8483333333333 | AS17: 31.5660003908333 | AT17: 26.6875 | AU17: 21.1369819305524 | AV17: 20.8290544327249 | AW17: 18.6332851199601 | AX17: 17.9842728930413 | AY17: 16.5251037109246 | AZ17: 17.5156853679268 | BA17: 17.0494827336028 | BB17: 18.7644705946022 | BC17: 19.2004283143122 | BD17: 17.7544737854169 | BE17: 17.2300682381835 | BF17: 15.9949873679769 | BG17: 16.4086652627089 | BH17: 17.5903303177529 | BI17: 17.3567061146333 | BJ17: 14.4060016758329 | BK17: 12.793041927804 | BL17: 12.1419889531682 | BM17: 11.6198425058429 | BN17: 11.7619087610202 | BO17: 11.7194139566373 | BP17: 12.3852390680976 | BQ17: 13.149294481602
A18: American Samoa | B18: ASM | C18: Lending interest rate (%) | D18: FR.INR.LEND
